{"trial_id": "0", "hyperparameters": {"space": [{"class_name": "Choice", "config": {"name": "optimizer", "default": "adam", "conditions": [], "values": ["adam", "sigmoid", "rmsprop", "adadelta"], "ordered": false}}], "values": {"optimizer": "sigmoid"}}, "metrics": {"metrics": {}}, "score": null, "best_step": 0, "status": "FAILED", "message": "Traceback (most recent call last):\n  File \"c:\\Users\\hp\\anaconda3\\Lib\\site-packages\\keras_tuner\\src\\engine\\base_tuner.py\", line 274, in _try_run_and_update_trial\n    self._run_and_update_trial(trial, *fit_args, **fit_kwargs)\n  File \"c:\\Users\\hp\\anaconda3\\Lib\\site-packages\\keras_tuner\\src\\engine\\base_tuner.py\", line 239, in _run_and_update_trial\n    results = self.run_trial(trial, *fit_args, **fit_kwargs)\n              ^^^^^^^^^^^^^^^^^^^^^^^^^^^^^^^^^^^^^^^^^^^^^^\n  File \"c:\\Users\\hp\\anaconda3\\Lib\\site-packages\\keras_tuner\\src\\engine\\tuner.py\", line 314, in run_trial\n    obj_value = self._build_and_fit_model(trial, *args, **copied_kwargs)\n                ^^^^^^^^^^^^^^^^^^^^^^^^^^^^^^^^^^^^^^^^^^^^^^^^^^^^^^^^\n  File \"c:\\Users\\hp\\anaconda3\\Lib\\site-packages\\keras_tuner\\src\\engine\\tuner.py\", line 232, in _build_and_fit_model\n    model = self._try_build(hp)\n            ^^^^^^^^^^^^^^^^^^^\n  File \"c:\\Users\\hp\\anaconda3\\Lib\\site-packages\\keras_tuner\\src\\engine\\tuner.py\", line 164, in _try_build\n    model = self._build_hypermodel(hp)\n            ^^^^^^^^^^^^^^^^^^^^^^^^^^\n  File \"c:\\Users\\hp\\anaconda3\\Lib\\site-packages\\keras_tuner\\src\\engine\\tuner.py\", line 155, in _build_hypermodel\n    model = self.hypermodel.build(hp)\n            ^^^^^^^^^^^^^^^^^^^^^^^^^\n  File \"C:\\Users\\hp\\AppData\\Local\\Temp\\ipykernel_15268\\4091195494.py\", line 8, in build_model\n    model.compile(optimizer=hp.Choice('optimizer',values = ['adam','sigmoid','rmsprop','adadelta']),loss=\"binary_crossentropy\",metrics=['acc'])\n  File \"c:\\Users\\hp\\anaconda3\\Lib\\site-packages\\keras\\src\\utils\\traceback_utils.py\", line 122, in error_handler\n    raise e.with_traceback(filtered_tb) from None\n  File \"c:\\Users\\hp\\anaconda3\\Lib\\site-packages\\keras\\src\\optimizers\\__init__.py\", line 97, in get\n    raise ValueError(f\"Could not interpret optimizer identifier: {identifier}\")\nValueError: Could not interpret optimizer identifier: sigmoid\n"}